[2024-05-24T11:08:57.406+0000] {local_task_job_runner.py:120} INFO - ::group::Pre task execution logs
[2024-05-24T11:08:57.430+0000] {taskinstance.py:2076} INFO - Dependencies all met for dep_context=non-requeueable deps ti=<TaskInstance: my_weather_workflow_DAG_v03.transform_data_response manual__2024-05-24T10:45:36.975501+00:00 [queued]>
[2024-05-24T11:08:57.439+0000] {taskinstance.py:2076} INFO - Dependencies all met for dep_context=requeueable deps ti=<TaskInstance: my_weather_workflow_DAG_v03.transform_data_response manual__2024-05-24T10:45:36.975501+00:00 [queued]>
[2024-05-24T11:08:57.440+0000] {taskinstance.py:2306} INFO - Starting attempt 7 of 12
[2024-05-24T11:08:57.454+0000] {taskinstance.py:2330} INFO - Executing <Task(PythonOperator): transform_data_response> on 2024-05-24 10:45:36.975501+00:00
[2024-05-24T11:08:57.461+0000] {standard_task_runner.py:90} INFO - Running: ['***', 'tasks', 'run', 'my_weather_workflow_DAG_v03', 'transform_data_response', 'manual__2024-05-24T10:45:36.975501+00:00', '--job-id', '56', '--raw', '--subdir', 'DAGS_FOLDER/weather_dag.py', '--cfg-path', '/tmp/tmpm95t1mrt']
[2024-05-24T11:08:57.463+0000] {logging_mixin.py:188} WARNING - /home/***/.local/lib/python3.12/site-packages/***/task/task_runner/standard_task_runner.py:61 DeprecationWarning: This process (pid=1914) is multi-threaded, use of fork() may lead to deadlocks in the child.
[2024-05-24T11:08:57.465+0000] {standard_task_runner.py:91} INFO - Job 56: Subtask transform_data_response
[2024-05-24T11:08:57.465+0000] {standard_task_runner.py:63} INFO - Started process 1916 to run task
[2024-05-24T11:08:57.523+0000] {task_command.py:426} INFO - Running <TaskInstance: my_weather_workflow_DAG_v03.transform_data_response manual__2024-05-24T10:45:36.975501+00:00 [running]> on host 6ab40057742d
[2024-05-24T11:08:57.760+0000] {taskinstance.py:2648} INFO - Exporting env vars: AIRFLOW_CTX_DAG_OWNER='Khang' AIRFLOW_CTX_DAG_ID='my_weather_workflow_DAG_v03' AIRFLOW_CTX_TASK_ID='transform_data_response' AIRFLOW_CTX_EXECUTION_DATE='2024-05-24T10:45:36.975501+00:00' AIRFLOW_CTX_TRY_NUMBER='7' AIRFLOW_CTX_DAG_RUN_ID='manual__2024-05-24T10:45:36.975501+00:00'
[2024-05-24T11:08:57.762+0000] {taskinstance.py:430} INFO - ::endgroup::
[2024-05-24T11:08:57.790+0000] {taskinstance.py:441} INFO - ::group::Post task execution logs
[2024-05-24T11:08:57.791+0000] {taskinstance.py:2905} ERROR - Task failed with exception
Traceback (most recent call last):
  File "/home/airflow/.local/lib/python3.12/site-packages/airflow/models/taskinstance.py", line 465, in _execute_task
    result = _execute_callable(context=context, **execute_callable_kwargs)
             ^^^^^^^^^^^^^^^^^^^^^^^^^^^^^^^^^^^^^^^^^^^^^^^^^^^^^^^^^^^^^
  File "/home/airflow/.local/lib/python3.12/site-packages/airflow/models/taskinstance.py", line 432, in _execute_callable
    return execute_callable(context=context, **execute_callable_kwargs)
           ^^^^^^^^^^^^^^^^^^^^^^^^^^^^^^^^^^^^^^^^^^^^^^^^^^^^^^^^^^^^
  File "/home/airflow/.local/lib/python3.12/site-packages/airflow/models/baseoperator.py", line 400, in wrapper
    return func(self, *args, **kwargs)
           ^^^^^^^^^^^^^^^^^^^^^^^^^^^
  File "/home/airflow/.local/lib/python3.12/site-packages/airflow/operators/python.py", line 235, in execute
    return_value = self.execute_callable()
                   ^^^^^^^^^^^^^^^^^^^^^^^
  File "/home/airflow/.local/lib/python3.12/site-packages/airflow/operators/python.py", line 252, in execute_callable
    return self.python_callable(*self.op_args, **self.op_kwargs)
           ^^^^^^^^^^^^^^^^^^^^^^^^^^^^^^^^^^^^^^^^^^^^^^^^^^^^^
  File "/opt/airflow/dags/weather_dag.py", line 48, in transform_data
    to_csv(transformed_data)
  File "/opt/airflow/dags/weather_dag.py", line 59, in to_csv
    if not os.path(directory):
           ^^^^^^^^^^^^^^^^^^
TypeError: 'module' object is not callable
[2024-05-24T11:08:57.809+0000] {taskinstance.py:1206} INFO - Marking task as UP_FOR_RETRY. dag_id=my_weather_workflow_DAG_v03, task_id=transform_data_response, run_id=manual__2024-05-24T10:45:36.975501+00:00, execution_date=20240524T104536, start_date=20240524T110857, end_date=20240524T110857
[2024-05-24T11:08:57.822+0000] {standard_task_runner.py:110} ERROR - Failed to execute job 56 for task transform_data_response ('module' object is not callable; 1916)
[2024-05-24T11:08:57.841+0000] {local_task_job_runner.py:240} INFO - Task exited with return code 1
[2024-05-24T11:08:57.861+0000] {taskinstance.py:3498} INFO - 0 downstream tasks scheduled from follow-on schedule check
[2024-05-24T11:08:57.865+0000] {local_task_job_runner.py:222} INFO - ::endgroup::
