[2024-06-01T04:39:03.828+0000] {local_task_job_runner.py:120} INFO - ::group::Pre task execution logs
[2024-06-01T04:39:03.851+0000] {taskinstance.py:2076} INFO - Dependencies all met for dep_context=non-requeueable deps ti=<TaskInstance: my_weather_workflow_DAG_v04.group_tasks.extract_weather_data_from_api manual__2024-06-01T04:21:04.663663+00:00 [queued]>
[2024-06-01T04:39:03.860+0000] {taskinstance.py:2076} INFO - Dependencies all met for dep_context=requeueable deps ti=<TaskInstance: my_weather_workflow_DAG_v04.group_tasks.extract_weather_data_from_api manual__2024-06-01T04:21:04.663663+00:00 [queued]>
[2024-06-01T04:39:03.861+0000] {taskinstance.py:2306} INFO - Starting attempt 7 of 12
[2024-06-01T04:39:03.876+0000] {taskinstance.py:2330} INFO - Executing <Task(PythonOperator): group_tasks.extract_weather_data_from_api> on 2024-06-01 04:21:04.663663+00:00
[2024-06-01T04:39:03.884+0000] {logging_mixin.py:188} WARNING - /home/***/.local/lib/python3.12/site-packages/***/task/task_runner/standard_task_runner.py:61 DeprecationWarning: This process (pid=3967) is multi-threaded, use of fork() may lead to deadlocks in the child.
[2024-06-01T04:39:03.885+0000] {standard_task_runner.py:63} INFO - Started process 3969 to run task
[2024-06-01T04:39:03.884+0000] {standard_task_runner.py:90} INFO - Running: ['***', 'tasks', 'run', 'my_weather_workflow_DAG_v04', 'group_tasks.extract_weather_data_from_api', 'manual__2024-06-01T04:21:04.663663+00:00', '--job-id', '483', '--raw', '--subdir', 'DAGS_FOLDER/weather_dag.py', '--cfg-path', '/tmp/tmp4gujdync']
[2024-06-01T04:39:03.887+0000] {standard_task_runner.py:91} INFO - Job 483: Subtask group_tasks.extract_weather_data_from_api
[2024-06-01T04:39:03.954+0000] {task_command.py:426} INFO - Running <TaskInstance: my_weather_workflow_DAG_v04.group_tasks.extract_weather_data_from_api manual__2024-06-01T04:21:04.663663+00:00 [running]> on host cd9caf1c47f0
[2024-06-01T04:39:04.108+0000] {taskinstance.py:2648} INFO - Exporting env vars: AIRFLOW_CTX_DAG_OWNER='Khang' AIRFLOW_CTX_DAG_ID='my_weather_workflow_DAG_v04' AIRFLOW_CTX_TASK_ID='group_tasks.extract_weather_data_from_api' AIRFLOW_CTX_EXECUTION_DATE='2024-06-01T04:21:04.663663+00:00' AIRFLOW_CTX_TRY_NUMBER='7' AIRFLOW_CTX_DAG_RUN_ID='manual__2024-06-01T04:21:04.663663+00:00'
[2024-06-01T04:39:04.110+0000] {taskinstance.py:430} INFO - ::endgroup::
[2024-06-01T04:39:04.127+0000] {baseoperator.py:399} WARNING - SimpleHttpOperator.execute cannot be called outside TaskInstance!
[2024-06-01T04:39:04.128+0000] {http.py:169} INFO - Calling HTTP method
[2024-06-01T04:39:04.147+0000] {base.py:84} INFO - Using connection ID 'weather_map_api_connection' for task execution.
[2024-06-01T04:39:04.162+0000] {base.py:84} INFO - Using connection ID 'weather_map_api_connection' for task execution.
[2024-06-01T04:39:04.465+0000] {http.py:208} INFO - {"coord":{"lon":108.1578,"lat":10.937},"weather":[{"id":804,"main":"Clouds","description":"overcast clouds","icon":"04d"}],"base":"stations","main":{"temp":304.36,"feels_like":309.53,"temp_min":304.36,"temp_max":304.36,"pressure":1010,"humidity":64,"sea_level":1010,"grnd_level":1004},"visibility":10000,"wind":{"speed":5.49,"deg":206,"gust":6.03},"clouds":{"all":98},"dt":1717216742,"sys":{"country":"VN","sunrise":1717194224,"sunset":1717240021},"timezone":25200,"id":1571058,"name":"Phan Thiet","cod":200}
[2024-06-01T04:39:04.467+0000] {taskinstance.py:441} INFO - ::group::Post task execution logs
[2024-06-01T04:39:04.468+0000] {taskinstance.py:2905} ERROR - Task failed with exception
Traceback (most recent call last):
  File "/home/airflow/.local/lib/python3.12/site-packages/airflow/models/taskinstance.py", line 465, in _execute_task
    result = _execute_callable(context=context, **execute_callable_kwargs)
             ^^^^^^^^^^^^^^^^^^^^^^^^^^^^^^^^^^^^^^^^^^^^^^^^^^^^^^^^^^^^^
  File "/home/airflow/.local/lib/python3.12/site-packages/airflow/models/taskinstance.py", line 432, in _execute_callable
    return execute_callable(context=context, **execute_callable_kwargs)
           ^^^^^^^^^^^^^^^^^^^^^^^^^^^^^^^^^^^^^^^^^^^^^^^^^^^^^^^^^^^^
  File "/home/airflow/.local/lib/python3.12/site-packages/airflow/models/baseoperator.py", line 400, in wrapper
    return func(self, *args, **kwargs)
           ^^^^^^^^^^^^^^^^^^^^^^^^^^^
  File "/home/airflow/.local/lib/python3.12/site-packages/airflow/operators/python.py", line 235, in execute
    return_value = self.execute_callable()
                   ^^^^^^^^^^^^^^^^^^^^^^^
  File "/home/airflow/.local/lib/python3.12/site-packages/airflow/operators/python.py", line 252, in execute_callable
    return self.python_callable(*self.op_args, **self.op_kwargs)
           ^^^^^^^^^^^^^^^^^^^^^^^^^^^^^^^^^^^^^^^^^^^^^^^^^^^^^
  File "/opt/airflow/dags/weather_dag.py", line 127, in extract_weather_data_from_api
    ti.xcom_push(task_ids='extract_data', key='data_weather')
  File "/home/airflow/.local/lib/python3.12/site-packages/airflow/utils/session.py", line 79, in wrapper
    return func(*args, session=session, **kwargs)
           ^^^^^^^^^^^^^^^^^^^^^^^^^^^^^^^^^^^^^^
TypeError: TaskInstance.xcom_push() got an unexpected keyword argument 'task_ids'
[2024-06-01T04:39:04.490+0000] {taskinstance.py:1206} INFO - Marking task as UP_FOR_RETRY. dag_id=my_weather_workflow_DAG_v04, task_id=group_tasks.extract_weather_data_from_api, run_id=manual__2024-06-01T04:21:04.663663+00:00, execution_date=20240601T042104, start_date=20240601T043903, end_date=20240601T043904
[2024-06-01T04:39:04.503+0000] {standard_task_runner.py:110} ERROR - Failed to execute job 483 for task group_tasks.extract_weather_data_from_api (TaskInstance.xcom_push() got an unexpected keyword argument 'task_ids'; 3969)
[2024-06-01T04:39:04.542+0000] {local_task_job_runner.py:240} INFO - Task exited with return code 1
[2024-06-01T04:39:04.573+0000] {taskinstance.py:3498} INFO - 0 downstream tasks scheduled from follow-on schedule check
[2024-06-01T04:39:04.576+0000] {local_task_job_runner.py:222} INFO - ::endgroup::
