[2024-05-25T15:21:56.613+0000] {local_task_job_runner.py:120} INFO - ::group::Pre task execution logs
[2024-05-25T15:21:56.644+0000] {taskinstance.py:2076} INFO - Dependencies all met for dep_context=non-requeueable deps ti=<TaskInstance: my_weather_workflow_DAG_v03.up_load_to_s3 manual__2024-05-25T15:21:55.351143+00:00 [queued]>
[2024-05-25T15:21:56.657+0000] {taskinstance.py:2076} INFO - Dependencies all met for dep_context=requeueable deps ti=<TaskInstance: my_weather_workflow_DAG_v03.up_load_to_s3 manual__2024-05-25T15:21:55.351143+00:00 [queued]>
[2024-05-25T15:21:56.658+0000] {taskinstance.py:2306} INFO - Starting attempt 1 of 6
[2024-05-25T15:21:56.676+0000] {taskinstance.py:2330} INFO - Executing <Task(PythonOperator): up_load_to_s3> on 2024-05-25 15:21:55.351143+00:00
[2024-05-25T15:21:56.686+0000] {standard_task_runner.py:90} INFO - Running: ['***', 'tasks', 'run', 'my_weather_workflow_DAG_v03', 'up_load_to_s3', 'manual__2024-05-25T15:21:55.351143+00:00', '--job-id', '141', '--raw', '--subdir', 'DAGS_FOLDER/weather_dag.py', '--cfg-path', '/tmp/tmpzqesvv18']
[2024-05-25T15:21:56.690+0000] {standard_task_runner.py:91} INFO - Job 141: Subtask up_load_to_s3
[2024-05-25T15:21:56.692+0000] {logging_mixin.py:188} WARNING - /home/***/.local/lib/python3.12/site-packages/***/task/task_runner/standard_task_runner.py:61 DeprecationWarning: This process (pid=2252) is multi-threaded, use of fork() may lead to deadlocks in the child.
[2024-05-25T15:21:56.694+0000] {standard_task_runner.py:63} INFO - Started process 2255 to run task
[2024-05-25T15:21:56.779+0000] {task_command.py:426} INFO - Running <TaskInstance: my_weather_workflow_DAG_v03.up_load_to_s3 manual__2024-05-25T15:21:55.351143+00:00 [running]> on host c0a968b5acd8
[2024-05-25T15:21:56.951+0000] {taskinstance.py:2648} INFO - Exporting env vars: AIRFLOW_CTX_DAG_OWNER='Khang' AIRFLOW_CTX_DAG_ID='my_weather_workflow_DAG_v03' AIRFLOW_CTX_TASK_ID='up_load_to_s3' AIRFLOW_CTX_EXECUTION_DATE='2024-05-25T15:21:55.351143+00:00' AIRFLOW_CTX_TRY_NUMBER='1' AIRFLOW_CTX_DAG_RUN_ID='manual__2024-05-25T15:21:55.351143+00:00'
[2024-05-25T15:21:56.953+0000] {taskinstance.py:430} INFO - ::endgroup::
[2024-05-25T15:21:57.021+0000] {base.py:84} INFO - Using connection ID 'weather_map_s3_connection' for task execution.
[2024-05-25T15:21:57.021+0000] {connection_wrapper.py:384} INFO - AWS Connection (conn_id='weather_map_s3_connection', conn_type='aws') credentials retrieved from login and password.
[2024-05-25T15:21:57.885+0000] {taskinstance.py:441} INFO - ::group::Post task execution logs
[2024-05-25T15:21:57.886+0000] {taskinstance.py:2905} ERROR - Task failed with exception
Traceback (most recent call last):
  File "/home/airflow/.local/lib/python3.12/site-packages/airflow/models/taskinstance.py", line 465, in _execute_task
    result = _execute_callable(context=context, **execute_callable_kwargs)
             ^^^^^^^^^^^^^^^^^^^^^^^^^^^^^^^^^^^^^^^^^^^^^^^^^^^^^^^^^^^^^
  File "/home/airflow/.local/lib/python3.12/site-packages/airflow/models/taskinstance.py", line 432, in _execute_callable
    return execute_callable(context=context, **execute_callable_kwargs)
           ^^^^^^^^^^^^^^^^^^^^^^^^^^^^^^^^^^^^^^^^^^^^^^^^^^^^^^^^^^^^
  File "/home/airflow/.local/lib/python3.12/site-packages/airflow/models/baseoperator.py", line 400, in wrapper
    return func(self, *args, **kwargs)
           ^^^^^^^^^^^^^^^^^^^^^^^^^^^
  File "/home/airflow/.local/lib/python3.12/site-packages/airflow/operators/python.py", line 235, in execute
    return_value = self.execute_callable()
                   ^^^^^^^^^^^^^^^^^^^^^^^
  File "/home/airflow/.local/lib/python3.12/site-packages/airflow/operators/python.py", line 252, in execute_callable
    return self.python_callable(*self.op_args, **self.op_kwargs)
           ^^^^^^^^^^^^^^^^^^^^^^^^^^^^^^^^^^^^^^^^^^^^^^^^^^^^^
  File "/opt/airflow/dags/weather_dag.py", line 64, in up_load_to_s3
    hook.load_file(filename='/opt/airflow/data-transform/{file_name}', key=file_name, bucket_name='weather-api-airflow')
  File "/home/airflow/.local/lib/python3.12/site-packages/airflow/providers/amazon/aws/hooks/s3.py", line 135, in wrapper
    return func(*bound_args.args, **bound_args.kwargs)
           ^^^^^^^^^^^^^^^^^^^^^^^^^^^^^^^^^^^^^^^^^^^
  File "/home/airflow/.local/lib/python3.12/site-packages/airflow/providers/amazon/aws/hooks/s3.py", line 89, in wrapper
    return func(*bound_args.args, **bound_args.kwargs)
           ^^^^^^^^^^^^^^^^^^^^^^^^^^^^^^^^^^^^^^^^^^^
  File "/home/airflow/.local/lib/python3.12/site-packages/airflow/providers/amazon/aws/hooks/s3.py", line 1082, in load_file
    if not replace and self.check_for_key(key, bucket_name):
                       ^^^^^^^^^^^^^^^^^^^^^^^^^^^^^^^^^^^^
  File "/home/airflow/.local/lib/python3.12/site-packages/airflow/providers/amazon/aws/hooks/s3.py", line 135, in wrapper
    return func(*bound_args.args, **bound_args.kwargs)
           ^^^^^^^^^^^^^^^^^^^^^^^^^^^^^^^^^^^^^^^^^^^
  File "/home/airflow/.local/lib/python3.12/site-packages/airflow/providers/amazon/aws/hooks/s3.py", line 89, in wrapper
    return func(*bound_args.args, **bound_args.kwargs)
           ^^^^^^^^^^^^^^^^^^^^^^^^^^^^^^^^^^^^^^^^^^^
  File "/home/airflow/.local/lib/python3.12/site-packages/airflow/providers/amazon/aws/hooks/s3.py", line 922, in check_for_key
    obj = self.head_object(key, bucket_name)
          ^^^^^^^^^^^^^^^^^^^^^^^^^^^^^^^^^^
  File "/home/airflow/.local/lib/python3.12/site-packages/airflow/providers/amazon/aws/hooks/s3.py", line 135, in wrapper
    return func(*bound_args.args, **bound_args.kwargs)
           ^^^^^^^^^^^^^^^^^^^^^^^^^^^^^^^^^^^^^^^^^^^
  File "/home/airflow/.local/lib/python3.12/site-packages/airflow/providers/amazon/aws/hooks/s3.py", line 89, in wrapper
    return func(*bound_args.args, **bound_args.kwargs)
           ^^^^^^^^^^^^^^^^^^^^^^^^^^^^^^^^^^^^^^^^^^^
  File "/home/airflow/.local/lib/python3.12/site-packages/airflow/providers/amazon/aws/hooks/s3.py", line 902, in head_object
    return self.get_conn().head_object(Bucket=bucket_name, Key=key)
           ^^^^^^^^^^^^^^^^^^^^^^^^^^^^^^^^^^^^^^^^^^^^^^^^^^^^^^^^
  File "/home/airflow/.local/lib/python3.12/site-packages/botocore/client.py", line 553, in _api_call
    return self._make_api_call(operation_name, kwargs)
           ^^^^^^^^^^^^^^^^^^^^^^^^^^^^^^^^^^^^^^^^^^^
  File "/home/airflow/.local/lib/python3.12/site-packages/botocore/client.py", line 962, in _make_api_call
    request_dict = self._convert_to_request_dict(
                   ^^^^^^^^^^^^^^^^^^^^^^^^^^^^^^
  File "/home/airflow/.local/lib/python3.12/site-packages/botocore/client.py", line 1036, in _convert_to_request_dict
    request_dict = self._serializer.serialize_to_request(
                   ^^^^^^^^^^^^^^^^^^^^^^^^^^^^^^^^^^^^^^
  File "/home/airflow/.local/lib/python3.12/site-packages/botocore/validate.py", line 381, in serialize_to_request
    raise ParamValidationError(report=report.generate_report())
botocore.exceptions.ParamValidationError: Parameter validation failed:
Invalid type for parameter Key, value: None, type: <class 'NoneType'>, valid types: <class 'str'>
[2024-05-25T15:21:57.902+0000] {taskinstance.py:1206} INFO - Marking task as UP_FOR_RETRY. dag_id=my_weather_workflow_DAG_v03, task_id=up_load_to_s3, run_id=manual__2024-05-25T15:21:55.351143+00:00, execution_date=20240525T152155, start_date=20240525T152156, end_date=20240525T152157
[2024-05-25T15:21:57.916+0000] {standard_task_runner.py:110} ERROR - Failed to execute job 141 for task up_load_to_s3 (Parameter validation failed:
Invalid type for parameter Key, value: None, type: <class 'NoneType'>, valid types: <class 'str'>; 2255)
[2024-05-25T15:21:57.954+0000] {local_task_job_runner.py:240} INFO - Task exited with return code 1
[2024-05-25T15:21:57.978+0000] {taskinstance.py:3498} INFO - 0 downstream tasks scheduled from follow-on schedule check
[2024-05-25T15:21:57.981+0000] {local_task_job_runner.py:222} INFO - ::endgroup::
