[2024-05-29T10:37:17.882+0000] {local_task_job_runner.py:120} INFO - ::group::Pre task execution logs
[2024-05-29T10:37:17.908+0000] {taskinstance.py:2076} INFO - Dependencies all met for dep_context=non-requeueable deps ti=<TaskInstance: my_weather_workflow_DAG_v03.is_weather_api_ready manual__2024-05-29T10:37:16.739803+00:00 [queued]>
[2024-05-29T10:37:17.920+0000] {taskinstance.py:2076} INFO - Dependencies all met for dep_context=requeueable deps ti=<TaskInstance: my_weather_workflow_DAG_v03.is_weather_api_ready manual__2024-05-29T10:37:16.739803+00:00 [queued]>
[2024-05-29T10:37:17.921+0000] {taskinstance.py:2306} INFO - Starting attempt 1 of 6
[2024-05-29T10:37:17.941+0000] {taskinstance.py:2330} INFO - Executing <Task(HttpSensor): is_weather_api_ready> on 2024-05-29 10:37:16.739803+00:00
[2024-05-29T10:37:17.953+0000] {standard_task_runner.py:90} INFO - Running: ['***', 'tasks', 'run', 'my_weather_workflow_DAG_v03', 'is_weather_api_ready', 'manual__2024-05-29T10:37:16.739803+00:00', '--job-id', '14', '--raw', '--subdir', 'DAGS_FOLDER/weather_dag.py', '--cfg-path', '/tmp/tmpas04ancl']
[2024-05-29T10:37:17.957+0000] {standard_task_runner.py:91} INFO - Job 14: Subtask is_weather_api_ready
[2024-05-29T10:37:17.959+0000] {logging_mixin.py:188} WARNING - /home/***/.local/lib/python3.12/site-packages/***/task/task_runner/standard_task_runner.py:61 DeprecationWarning: This process (pid=580) is multi-threaded, use of fork() may lead to deadlocks in the child.
[2024-05-29T10:37:17.961+0000] {standard_task_runner.py:63} INFO - Started process 582 to run task
[2024-05-29T10:37:18.054+0000] {task_command.py:426} INFO - Running <TaskInstance: my_weather_workflow_DAG_v03.is_weather_api_ready manual__2024-05-29T10:37:16.739803+00:00 [running]> on host cd9caf1c47f0
[2024-05-29T10:37:18.172+0000] {taskinstance.py:2648} INFO - Exporting env vars: AIRFLOW_CTX_DAG_OWNER='Khang' AIRFLOW_CTX_DAG_ID='my_weather_workflow_DAG_v03' AIRFLOW_CTX_TASK_ID='is_weather_api_ready' AIRFLOW_CTX_EXECUTION_DATE='2024-05-29T10:37:16.739803+00:00' AIRFLOW_CTX_TRY_NUMBER='1' AIRFLOW_CTX_DAG_RUN_ID='manual__2024-05-29T10:37:16.739803+00:00'
[2024-05-29T10:37:18.174+0000] {taskinstance.py:430} INFO - ::endgroup::
[2024-05-29T10:37:18.187+0000] {baseoperator.py:399} WARNING - HttpSensor.execute cannot be called outside TaskInstance!
[2024-05-29T10:37:18.187+0000] {http.py:137} INFO - Poking: /data/2.5/weather?lat=10.762622&lon=106.660172&appid=a0548aecbb168d6f8f01a57f64ba318c
[2024-05-29T10:37:18.203+0000] {base.py:84} INFO - Using connection ID 'weather_map_api_connection' for task execution.
[2024-05-29T10:37:18.366+0000] {http.py:199} ERROR - HTTP error: Unauthorized
[2024-05-29T10:37:18.367+0000] {http.py:200} ERROR - {"cod":401, "message": "Invalid API key. Please see https://openweathermap.org/faq#error401 for more info."}
[2024-05-29T10:37:18.368+0000] {taskinstance.py:441} INFO - ::group::Post task execution logs
[2024-05-29T10:37:18.380+0000] {taskinstance.py:2905} ERROR - Task failed with exception
Traceback (most recent call last):
  File "/home/airflow/.local/lib/python3.12/site-packages/airflow/providers/http/hooks/http.py", line 197, in check_response
    response.raise_for_status()
  File "/home/airflow/.local/lib/python3.12/site-packages/requests/models.py", line 1021, in raise_for_status
    raise HTTPError(http_error_msg, response=self)
requests.exceptions.HTTPError: 401 Client Error: Unauthorized for url: https://api.openweathermap.org/data/2.5/weather?lat=10.762622&lon=106.660172&appid=a0548aecbb168d6f8f01a57f64ba318c

During handling of the above exception, another exception occurred:

Traceback (most recent call last):
  File "/home/airflow/.local/lib/python3.12/site-packages/airflow/models/taskinstance.py", line 465, in _execute_task
    result = _execute_callable(context=context, **execute_callable_kwargs)
             ^^^^^^^^^^^^^^^^^^^^^^^^^^^^^^^^^^^^^^^^^^^^^^^^^^^^^^^^^^^^^
  File "/home/airflow/.local/lib/python3.12/site-packages/airflow/models/taskinstance.py", line 432, in _execute_callable
    return execute_callable(context=context, **execute_callable_kwargs)
           ^^^^^^^^^^^^^^^^^^^^^^^^^^^^^^^^^^^^^^^^^^^^^^^^^^^^^^^^^^^^
  File "/home/airflow/.local/lib/python3.12/site-packages/airflow/models/baseoperator.py", line 400, in wrapper
    return func(self, *args, **kwargs)
           ^^^^^^^^^^^^^^^^^^^^^^^^^^^
  File "/home/airflow/.local/lib/python3.12/site-packages/airflow/providers/http/sensors/http.py", line 164, in execute
    super().execute(context=context)
  File "/home/airflow/.local/lib/python3.12/site-packages/airflow/models/baseoperator.py", line 400, in wrapper
    return func(self, *args, **kwargs)
           ^^^^^^^^^^^^^^^^^^^^^^^^^^^
  File "/home/airflow/.local/lib/python3.12/site-packages/airflow/sensors/base.py", line 264, in execute
    raise e
  File "/home/airflow/.local/lib/python3.12/site-packages/airflow/sensors/base.py", line 246, in execute
    poke_return = self.poke(context)
                  ^^^^^^^^^^^^^^^^^^
  File "/home/airflow/.local/lib/python3.12/site-packages/airflow/providers/http/sensors/http.py", line 158, in poke
    raise exc
  File "/home/airflow/.local/lib/python3.12/site-packages/airflow/providers/http/sensors/http.py", line 139, in poke
    response = hook.run(
               ^^^^^^^^^
  File "/home/airflow/.local/lib/python3.12/site-packages/airflow/providers/http/hooks/http.py", line 187, in run
    return self.run_and_check(session, prepped_request, extra_options)
           ^^^^^^^^^^^^^^^^^^^^^^^^^^^^^^^^^^^^^^^^^^^^^^^^^^^^^^^^^^^
  File "/home/airflow/.local/lib/python3.12/site-packages/airflow/providers/http/hooks/http.py", line 238, in run_and_check
    self.check_response(response)
  File "/home/airflow/.local/lib/python3.12/site-packages/airflow/providers/http/hooks/http.py", line 201, in check_response
    raise AirflowException(str(response.status_code) + ":" + response.reason)
airflow.exceptions.AirflowException: 401:Unauthorized
[2024-05-29T10:37:18.386+0000] {taskinstance.py:1206} INFO - Marking task as UP_FOR_RETRY. dag_id=my_weather_workflow_DAG_v03, task_id=is_weather_api_ready, run_id=manual__2024-05-29T10:37:16.739803+00:00, execution_date=20240529T103716, start_date=20240529T103717, end_date=20240529T103718
[2024-05-29T10:37:18.400+0000] {standard_task_runner.py:110} ERROR - Failed to execute job 14 for task is_weather_api_ready (401:Unauthorized; 582)
[2024-05-29T10:37:18.418+0000] {local_task_job_runner.py:240} INFO - Task exited with return code 1
[2024-05-29T10:37:18.435+0000] {logging_mixin.py:188} WARNING - /home/***/.local/lib/python3.12/site-packages/***/models/baseoperator.py:1296 AirflowProviderDeprecationWarning: Call to deprecated class SimpleHttpOperator. (Class `SimpleHttpOperator` is deprecated and will be removed in a future release. Please use `HttpOperator` instead.)
[2024-05-29T10:37:18.456+0000] {taskinstance.py:3498} INFO - 0 downstream tasks scheduled from follow-on schedule check
[2024-05-29T10:37:18.460+0000] {local_task_job_runner.py:222} INFO - ::endgroup::
