[2024-05-24T11:21:07.108+0000] {local_task_job_runner.py:120} INFO - ::group::Pre task execution logs
[2024-05-24T11:21:07.133+0000] {taskinstance.py:2076} INFO - Dependencies all met for dep_context=non-requeueable deps ti=<TaskInstance: my_weather_workflow_DAG_v03.transform_data_response manual__2024-05-24T11:21:01.618042+00:00 [queued]>
[2024-05-24T11:21:07.145+0000] {taskinstance.py:2076} INFO - Dependencies all met for dep_context=requeueable deps ti=<TaskInstance: my_weather_workflow_DAG_v03.transform_data_response manual__2024-05-24T11:21:01.618042+00:00 [queued]>
[2024-05-24T11:21:07.146+0000] {taskinstance.py:2306} INFO - Starting attempt 1 of 6
[2024-05-24T11:21:07.163+0000] {taskinstance.py:2330} INFO - Executing <Task(PythonOperator): transform_data_response> on 2024-05-24 11:21:01.618042+00:00
[2024-05-24T11:21:07.172+0000] {logging_mixin.py:188} WARNING - /home/***/.local/lib/python3.12/site-packages/***/task/task_runner/standard_task_runner.py:61 DeprecationWarning: This process (pid=2256) is multi-threaded, use of fork() may lead to deadlocks in the child.
[2024-05-24T11:21:07.175+0000] {standard_task_runner.py:63} INFO - Started process 2258 to run task
[2024-05-24T11:21:07.171+0000] {standard_task_runner.py:90} INFO - Running: ['***', 'tasks', 'run', 'my_weather_workflow_DAG_v03', 'transform_data_response', 'manual__2024-05-24T11:21:01.618042+00:00', '--job-id', '68', '--raw', '--subdir', 'DAGS_FOLDER/weather_dag.py', '--cfg-path', '/tmp/tmph7zypg2r']
[2024-05-24T11:21:07.176+0000] {standard_task_runner.py:91} INFO - Job 68: Subtask transform_data_response
[2024-05-24T11:21:07.244+0000] {task_command.py:426} INFO - Running <TaskInstance: my_weather_workflow_DAG_v03.transform_data_response manual__2024-05-24T11:21:01.618042+00:00 [running]> on host 6ab40057742d
[2024-05-24T11:21:07.491+0000] {taskinstance.py:2648} INFO - Exporting env vars: AIRFLOW_CTX_DAG_OWNER='Khang' AIRFLOW_CTX_DAG_ID='my_weather_workflow_DAG_v03' AIRFLOW_CTX_TASK_ID='transform_data_response' AIRFLOW_CTX_EXECUTION_DATE='2024-05-24T11:21:01.618042+00:00' AIRFLOW_CTX_TRY_NUMBER='1' AIRFLOW_CTX_DAG_RUN_ID='manual__2024-05-24T11:21:01.618042+00:00'
[2024-05-24T11:21:07.493+0000] {taskinstance.py:430} INFO - ::endgroup::
[2024-05-24T11:21:07.535+0000] {taskinstance.py:441} INFO - ::group::Post task execution logs
[2024-05-24T11:21:07.536+0000] {taskinstance.py:2905} ERROR - Task failed with exception
Traceback (most recent call last):
  File "/home/airflow/.local/lib/python3.12/site-packages/airflow/models/taskinstance.py", line 465, in _execute_task
    result = _execute_callable(context=context, **execute_callable_kwargs)
             ^^^^^^^^^^^^^^^^^^^^^^^^^^^^^^^^^^^^^^^^^^^^^^^^^^^^^^^^^^^^^
  File "/home/airflow/.local/lib/python3.12/site-packages/airflow/models/taskinstance.py", line 432, in _execute_callable
    return execute_callable(context=context, **execute_callable_kwargs)
           ^^^^^^^^^^^^^^^^^^^^^^^^^^^^^^^^^^^^^^^^^^^^^^^^^^^^^^^^^^^^
  File "/home/airflow/.local/lib/python3.12/site-packages/airflow/models/baseoperator.py", line 400, in wrapper
    return func(self, *args, **kwargs)
           ^^^^^^^^^^^^^^^^^^^^^^^^^^^
  File "/home/airflow/.local/lib/python3.12/site-packages/airflow/operators/python.py", line 235, in execute
    return_value = self.execute_callable()
                   ^^^^^^^^^^^^^^^^^^^^^^^
  File "/home/airflow/.local/lib/python3.12/site-packages/airflow/operators/python.py", line 252, in execute_callable
    return self.python_callable(*self.op_args, **self.op_kwargs)
           ^^^^^^^^^^^^^^^^^^^^^^^^^^^^^^^^^^^^^^^^^^^^^^^^^^^^^
  File "/opt/airflow/dags/weather_dag.py", line 48, in transform_data
    to_csv(transformed_data)
  File "/opt/airflow/dags/weather_dag.py", line 60, in to_csv
    os.mkdir(directory)
PermissionError: [Errno 13] Permission denied: '../data-transformed'
[2024-05-24T11:21:07.561+0000] {taskinstance.py:1206} INFO - Marking task as UP_FOR_RETRY. dag_id=my_weather_workflow_DAG_v03, task_id=transform_data_response, run_id=manual__2024-05-24T11:21:01.618042+00:00, execution_date=20240524T112101, start_date=20240524T112107, end_date=20240524T112107
[2024-05-24T11:21:07.576+0000] {standard_task_runner.py:110} ERROR - Failed to execute job 68 for task transform_data_response ([Errno 13] Permission denied: '../data-transformed'; 2258)
[2024-05-24T11:21:07.591+0000] {local_task_job_runner.py:240} INFO - Task exited with return code 1
[2024-05-24T11:21:07.615+0000] {taskinstance.py:3498} INFO - 0 downstream tasks scheduled from follow-on schedule check
[2024-05-24T11:21:07.618+0000] {local_task_job_runner.py:222} INFO - ::endgroup::
