[2024-05-24T10:39:17.226+0000] {local_task_job_runner.py:120} INFO - ::group::Pre task execution logs
[2024-05-24T10:39:17.246+0000] {taskinstance.py:2076} INFO - Dependencies all met for dep_context=non-requeueable deps ti=<TaskInstance: my_weather_workflow_DAG_v03.transform_data_response scheduled__2024-05-23T00:00:00+00:00 [queued]>
[2024-05-24T10:39:17.253+0000] {taskinstance.py:2076} INFO - Dependencies all met for dep_context=requeueable deps ti=<TaskInstance: my_weather_workflow_DAG_v03.transform_data_response scheduled__2024-05-23T00:00:00+00:00 [queued]>
[2024-05-24T10:39:17.254+0000] {taskinstance.py:2306} INFO - Starting attempt 2 of 6
[2024-05-24T10:39:17.267+0000] {taskinstance.py:2330} INFO - Executing <Task(PythonOperator): transform_data_response> on 2024-05-23 00:00:00+00:00
[2024-05-24T10:39:17.273+0000] {standard_task_runner.py:90} INFO - Running: ['***', 'tasks', 'run', 'my_weather_workflow_DAG_v03', 'transform_data_response', 'scheduled__2024-05-23T00:00:00+00:00', '--job-id', '37', '--raw', '--subdir', 'DAGS_FOLDER/weather_dag.py', '--cfg-path', '/tmp/tmpn4cnm7jd']
[2024-05-24T10:39:17.276+0000] {standard_task_runner.py:91} INFO - Job 37: Subtask transform_data_response
[2024-05-24T10:39:17.278+0000] {logging_mixin.py:188} WARNING - /home/***/.local/lib/python3.12/site-packages/***/task/task_runner/standard_task_runner.py:61 DeprecationWarning: This process (pid=1132) is multi-threaded, use of fork() may lead to deadlocks in the child.
[2024-05-24T10:39:17.280+0000] {standard_task_runner.py:63} INFO - Started process 1134 to run task
[2024-05-24T10:39:17.333+0000] {task_command.py:426} INFO - Running <TaskInstance: my_weather_workflow_DAG_v03.transform_data_response scheduled__2024-05-23T00:00:00+00:00 [running]> on host 6ab40057742d
[2024-05-24T10:39:17.548+0000] {taskinstance.py:2648} INFO - Exporting env vars: AIRFLOW_CTX_DAG_OWNER='Khang' AIRFLOW_CTX_DAG_ID='my_weather_workflow_DAG_v03' AIRFLOW_CTX_TASK_ID='transform_data_response' AIRFLOW_CTX_EXECUTION_DATE='2024-05-23T00:00:00+00:00' AIRFLOW_CTX_TRY_NUMBER='2' AIRFLOW_CTX_DAG_RUN_ID='scheduled__2024-05-23T00:00:00+00:00'
[2024-05-24T10:39:17.549+0000] {taskinstance.py:430} INFO - ::endgroup::
[2024-05-24T10:39:17.577+0000] {taskinstance.py:441} INFO - ::group::Post task execution logs
[2024-05-24T10:39:17.577+0000] {taskinstance.py:2905} ERROR - Task failed with exception
Traceback (most recent call last):
  File "/home/airflow/.local/lib/python3.12/site-packages/airflow/models/taskinstance.py", line 465, in _execute_task
    result = _execute_callable(context=context, **execute_callable_kwargs)
             ^^^^^^^^^^^^^^^^^^^^^^^^^^^^^^^^^^^^^^^^^^^^^^^^^^^^^^^^^^^^^
  File "/home/airflow/.local/lib/python3.12/site-packages/airflow/models/taskinstance.py", line 432, in _execute_callable
    return execute_callable(context=context, **execute_callable_kwargs)
           ^^^^^^^^^^^^^^^^^^^^^^^^^^^^^^^^^^^^^^^^^^^^^^^^^^^^^^^^^^^^
  File "/home/airflow/.local/lib/python3.12/site-packages/airflow/models/baseoperator.py", line 400, in wrapper
    return func(self, *args, **kwargs)
           ^^^^^^^^^^^^^^^^^^^^^^^^^^^
  File "/home/airflow/.local/lib/python3.12/site-packages/airflow/operators/python.py", line 235, in execute
    return_value = self.execute_callable()
                   ^^^^^^^^^^^^^^^^^^^^^^^
  File "/home/airflow/.local/lib/python3.12/site-packages/airflow/operators/python.py", line 252, in execute_callable
    return self.python_callable(*self.op_args, **self.op_kwargs)
           ^^^^^^^^^^^^^^^^^^^^^^^^^^^^^^^^^^^^^^^^^^^^^^^^^^^^^
  File "/opt/airflow/dags/weather_dag.py", line 47, in transform_data
    to_csv(transformed_data)
  File "/opt/airflow/dags/weather_dag.py", line 54, in to_csv
    df_data.to_csv(f'{datetime_string}.csv', index=False)
  File "/home/airflow/.local/lib/python3.12/site-packages/pandas/core/generic.py", line 3902, in to_csv
    return DataFrameRenderer(formatter).to_csv(
           ^^^^^^^^^^^^^^^^^^^^^^^^^^^^^^^^^^^^
  File "/home/airflow/.local/lib/python3.12/site-packages/pandas/io/formats/format.py", line 1152, in to_csv
    csv_formatter.save()
  File "/home/airflow/.local/lib/python3.12/site-packages/pandas/io/formats/csvs.py", line 247, in save
    with get_handle(
         ^^^^^^^^^^^
  File "/home/airflow/.local/lib/python3.12/site-packages/pandas/io/common.py", line 739, in get_handle
    check_parent_directory(str(handle))
  File "/home/airflow/.local/lib/python3.12/site-packages/pandas/io/common.py", line 604, in check_parent_directory
    raise OSError(rf"Cannot save file into a non-existent directory: '{parent}'")
OSError: Cannot save file into a non-existent directory: 'current_weather_data_hcm_24/05'
[2024-05-24T10:39:17.597+0000] {taskinstance.py:1206} INFO - Marking task as UP_FOR_RETRY. dag_id=my_weather_workflow_DAG_v03, task_id=transform_data_response, run_id=scheduled__2024-05-23T00:00:00+00:00, execution_date=20240523T000000, start_date=20240524T103917, end_date=20240524T103917
[2024-05-24T10:39:17.607+0000] {standard_task_runner.py:110} ERROR - Failed to execute job 37 for task transform_data_response (Cannot save file into a non-existent directory: 'current_weather_data_hcm_24/05'; 1134)
[2024-05-24T10:39:17.655+0000] {local_task_job_runner.py:240} INFO - Task exited with return code 1
[2024-05-24T10:39:17.674+0000] {taskinstance.py:3498} INFO - 0 downstream tasks scheduled from follow-on schedule check
[2024-05-24T10:39:17.676+0000] {local_task_job_runner.py:222} INFO - ::endgroup::
