[2024-06-01T14:46:01.440+0000] {local_task_job_runner.py:120} INFO - ::group::Pre task execution logs
[2024-06-01T14:46:01.484+0000] {taskinstance.py:2076} INFO - Dependencies all met for dep_context=non-requeueable deps ti=<TaskInstance: my_weather_workflow_DAG_v04.group_tasks.check_data_city_is_exist manual__2024-06-01T14:44:02.662915+00:00 [queued]>
[2024-06-01T14:46:01.504+0000] {taskinstance.py:2076} INFO - Dependencies all met for dep_context=requeueable deps ti=<TaskInstance: my_weather_workflow_DAG_v04.group_tasks.check_data_city_is_exist manual__2024-06-01T14:44:02.662915+00:00 [queued]>
[2024-06-01T14:46:01.506+0000] {taskinstance.py:2306} INFO - Starting attempt 2 of 7
[2024-06-01T14:46:01.526+0000] {taskinstance.py:2330} INFO - Executing <Task(BranchPythonOperator): group_tasks.check_data_city_is_exist> on 2024-06-01 14:44:02.662915+00:00
[2024-06-01T14:46:01.538+0000] {standard_task_runner.py:90} INFO - Running: ['***', 'tasks', 'run', 'my_weather_workflow_DAG_v04', 'group_tasks.check_data_city_is_exist', 'manual__2024-06-01T14:44:02.662915+00:00', '--job-id', '763', '--raw', '--subdir', 'DAGS_FOLDER/tasks_flow.py', '--cfg-path', '/tmp/tmprax19jbv']
[2024-06-01T14:46:01.543+0000] {standard_task_runner.py:91} INFO - Job 763: Subtask group_tasks.check_data_city_is_exist
[2024-06-01T14:46:01.547+0000] {logging_mixin.py:188} WARNING - /home/***/.local/lib/python3.12/site-packages/***/task/task_runner/standard_task_runner.py:61 DeprecationWarning: This process (pid=587) is multi-threaded, use of fork() may lead to deadlocks in the child.
[2024-06-01T14:46:01.550+0000] {standard_task_runner.py:63} INFO - Started process 589 to run task
[2024-06-01T14:46:01.619+0000] {task_command.py:426} INFO - Running <TaskInstance: my_weather_workflow_DAG_v04.group_tasks.check_data_city_is_exist manual__2024-06-01T14:44:02.662915+00:00 [running]> on host cd9caf1c47f0
[2024-06-01T14:46:01.729+0000] {taskinstance.py:2648} INFO - Exporting env vars: AIRFLOW_CTX_DAG_OWNER='Khang' AIRFLOW_CTX_DAG_ID='my_weather_workflow_DAG_v04' AIRFLOW_CTX_TASK_ID='group_tasks.check_data_city_is_exist' AIRFLOW_CTX_EXECUTION_DATE='2024-06-01T14:44:02.662915+00:00' AIRFLOW_CTX_TRY_NUMBER='2' AIRFLOW_CTX_DAG_RUN_ID='manual__2024-06-01T14:44:02.662915+00:00'
[2024-06-01T14:46:01.730+0000] {taskinstance.py:430} INFO - ::endgroup::
[2024-06-01T14:46:01.743+0000] {baseoperator.py:399} WARNING - BranchPythonOperator.execute cannot be called outside TaskInstance!
[2024-06-01T14:46:01.770+0000] {base.py:84} INFO - Using connection ID 'postgres_connection_id' for task execution.
[2024-06-01T14:46:01.779+0000] {sql.py:470} INFO - Running statement: SELECT COUNT(*) FROM cities WHERE wiki_id = 'Q36167';, parameters: None
[2024-06-01T14:46:01.782+0000] {sql.py:479} INFO - Rows affected: 1
[2024-06-01T14:46:01.783+0000] {python.py:237} INFO - Done. Returned value was: group_tasks.skip_insert_data_city
[2024-06-01T14:46:01.784+0000] {branch.py:36} INFO - Branch into group_tasks.skip_insert_data_city
[2024-06-01T14:46:01.784+0000] {skipmixin.py:178} INFO - Following branch group_tasks.skip_insert_data_city
[2024-06-01T14:46:01.785+0000] {taskinstance.py:441} INFO - ::group::Post task execution logs
[2024-06-01T14:46:01.800+0000] {taskinstance.py:2905} ERROR - Task failed with exception
Traceback (most recent call last):
  File "/home/airflow/.local/lib/python3.12/site-packages/airflow/models/taskinstance.py", line 465, in _execute_task
    result = _execute_callable(context=context, **execute_callable_kwargs)
             ^^^^^^^^^^^^^^^^^^^^^^^^^^^^^^^^^^^^^^^^^^^^^^^^^^^^^^^^^^^^^
  File "/home/airflow/.local/lib/python3.12/site-packages/airflow/models/taskinstance.py", line 432, in _execute_callable
    return execute_callable(context=context, **execute_callable_kwargs)
           ^^^^^^^^^^^^^^^^^^^^^^^^^^^^^^^^^^^^^^^^^^^^^^^^^^^^^^^^^^^^
  File "/home/airflow/.local/lib/python3.12/site-packages/airflow/models/baseoperator.py", line 400, in wrapper
    return func(self, *args, **kwargs)
           ^^^^^^^^^^^^^^^^^^^^^^^^^^^
  File "/home/airflow/.local/lib/python3.12/site-packages/airflow/operators/python.py", line 269, in execute
    return self.do_branch(context, super().execute(context))
           ^^^^^^^^^^^^^^^^^^^^^^^^^^^^^^^^^^^^^^^^^^^^^^^^^
  File "/home/airflow/.local/lib/python3.12/site-packages/airflow/operators/branch.py", line 37, in do_branch
    self.skip_all_except(context["ti"], branches_to_execute)
  File "/home/airflow/.local/lib/python3.12/site-packages/airflow/models/skipmixin.py", line 215, in skip_all_except
    raise AirflowException(
airflow.exceptions.AirflowException: 'branch_task_ids' must contain only valid task_ids. Invalid tasks found: {'group_tasks.skip_insert_data_city'}.
[2024-06-01T14:46:01.804+0000] {taskinstance.py:1206} INFO - Marking task as UP_FOR_RETRY. dag_id=my_weather_workflow_DAG_v04, task_id=group_tasks.check_data_city_is_exist, run_id=manual__2024-06-01T14:44:02.662915+00:00, execution_date=20240601T144402, start_date=20240601T144601, end_date=20240601T144601
[2024-06-01T14:46:01.816+0000] {standard_task_runner.py:110} ERROR - Failed to execute job 763 for task group_tasks.check_data_city_is_exist ('branch_task_ids' must contain only valid task_ids. Invalid tasks found: {'group_tasks.skip_insert_data_city'}.; 589)
[2024-06-01T14:46:01.845+0000] {local_task_job_runner.py:240} INFO - Task exited with return code 1
[2024-06-01T14:46:01.861+0000] {local_task_job_runner.py:222} INFO - ::endgroup::
