[2024-05-25T08:49:14.169+0000] {local_task_job_runner.py:120} INFO - ::group::Pre task execution logs
[2024-05-25T08:49:14.197+0000] {taskinstance.py:2076} INFO - Dependencies all met for dep_context=non-requeueable deps ti=<TaskInstance: my_weather_workflow_DAG_v03.transform_data_response manual__2024-05-25T08:13:51.839954+00:00 [queued]>
[2024-05-25T08:49:14.207+0000] {taskinstance.py:2076} INFO - Dependencies all met for dep_context=requeueable deps ti=<TaskInstance: my_weather_workflow_DAG_v03.transform_data_response manual__2024-05-25T08:13:51.839954+00:00 [queued]>
[2024-05-25T08:49:14.209+0000] {taskinstance.py:2306} INFO - Starting attempt 7 of 12
[2024-05-25T08:49:14.228+0000] {taskinstance.py:2330} INFO - Executing <Task(PythonOperator): transform_data_response> on 2024-05-25 08:13:51.839954+00:00
[2024-05-25T08:49:14.238+0000] {standard_task_runner.py:90} INFO - Running: ['***', 'tasks', 'run', 'my_weather_workflow_DAG_v03', 'transform_data_response', 'manual__2024-05-25T08:13:51.839954+00:00', '--job-id', '102', '--raw', '--subdir', 'DAGS_FOLDER/weather_dag.py', '--cfg-path', '/tmp/tmpmyg4gzr7']
[2024-05-25T08:49:14.241+0000] {standard_task_runner.py:91} INFO - Job 102: Subtask transform_data_response
[2024-05-25T08:49:14.242+0000] {logging_mixin.py:188} WARNING - /home/***/.local/lib/python3.12/site-packages/***/task/task_runner/standard_task_runner.py:61 DeprecationWarning: This process (pid=5491) is multi-threaded, use of fork() may lead to deadlocks in the child.
[2024-05-25T08:49:14.244+0000] {standard_task_runner.py:63} INFO - Started process 5493 to run task
[2024-05-25T08:49:14.344+0000] {task_command.py:426} INFO - Running <TaskInstance: my_weather_workflow_DAG_v03.transform_data_response manual__2024-05-25T08:13:51.839954+00:00 [running]> on host 6ab40057742d
[2024-05-25T08:49:14.704+0000] {taskinstance.py:2648} INFO - Exporting env vars: AIRFLOW_CTX_DAG_OWNER='Khang' AIRFLOW_CTX_DAG_ID='my_weather_workflow_DAG_v03' AIRFLOW_CTX_TASK_ID='transform_data_response' AIRFLOW_CTX_EXECUTION_DATE='2024-05-25T08:13:51.839954+00:00' AIRFLOW_CTX_TRY_NUMBER='7' AIRFLOW_CTX_DAG_RUN_ID='manual__2024-05-25T08:13:51.839954+00:00'
[2024-05-25T08:49:14.705+0000] {taskinstance.py:430} INFO - ::endgroup::
[2024-05-25T08:49:14.721+0000] {taskinstance.py:441} INFO - ::group::Post task execution logs
[2024-05-25T08:49:14.722+0000] {taskinstance.py:2905} ERROR - Task failed with exception
Traceback (most recent call last):
  File "/home/airflow/.local/lib/python3.12/site-packages/airflow/models/taskinstance.py", line 465, in _execute_task
    result = _execute_callable(context=context, **execute_callable_kwargs)
             ^^^^^^^^^^^^^^^^^^^^^^^^^^^^^^^^^^^^^^^^^^^^^^^^^^^^^^^^^^^^^
  File "/home/airflow/.local/lib/python3.12/site-packages/airflow/models/taskinstance.py", line 432, in _execute_callable
    return execute_callable(context=context, **execute_callable_kwargs)
           ^^^^^^^^^^^^^^^^^^^^^^^^^^^^^^^^^^^^^^^^^^^^^^^^^^^^^^^^^^^^
  File "/home/airflow/.local/lib/python3.12/site-packages/airflow/models/baseoperator.py", line 400, in wrapper
    return func(self, *args, **kwargs)
           ^^^^^^^^^^^^^^^^^^^^^^^^^^^
  File "/home/airflow/.local/lib/python3.12/site-packages/airflow/operators/python.py", line 235, in execute
    return_value = self.execute_callable()
                   ^^^^^^^^^^^^^^^^^^^^^^^
  File "/home/airflow/.local/lib/python3.12/site-packages/airflow/operators/python.py", line 252, in execute_callable
    return self.python_callable(*self.op_args, **self.op_kwargs)
           ^^^^^^^^^^^^^^^^^^^^^^^^^^^^^^^^^^^^^^^^^^^^^^^^^^^^^
  File "/opt/airflow/dags/weather_dag.py", line 82, in to_csv
    df_data.to_csv(f'{parent_path}/{file_name}.csv', index=False)
  File "/home/airflow/.local/lib/python3.12/site-packages/pandas/core/generic.py", line 3902, in to_csv
    return DataFrameRenderer(formatter).to_csv(
           ^^^^^^^^^^^^^^^^^^^^^^^^^^^^^^^^^^^^
  File "/home/airflow/.local/lib/python3.12/site-packages/pandas/io/formats/format.py", line 1152, in to_csv
    csv_formatter.save()
  File "/home/airflow/.local/lib/python3.12/site-packages/pandas/io/formats/csvs.py", line 247, in save
    with get_handle(
         ^^^^^^^^^^^
  File "/home/airflow/.local/lib/python3.12/site-packages/pandas/io/common.py", line 863, in get_handle
    handle = open(
             ^^^^^
PermissionError: [Errno 13] Permission denied: '/opt/current_weather_data_hcm_25052024:084914.csv'
[2024-05-25T08:49:14.746+0000] {taskinstance.py:1206} INFO - Marking task as UP_FOR_RETRY. dag_id=my_weather_workflow_DAG_v03, task_id=transform_data_response, run_id=manual__2024-05-25T08:13:51.839954+00:00, execution_date=20240525T081351, start_date=20240525T084914, end_date=20240525T084914
[2024-05-25T08:49:14.760+0000] {standard_task_runner.py:110} ERROR - Failed to execute job 102 for task transform_data_response ([Errno 13] Permission denied: '/opt/current_weather_data_hcm_25052024:084914.csv'; 5493)
[2024-05-25T08:49:14.781+0000] {local_task_job_runner.py:240} INFO - Task exited with return code 1
[2024-05-25T08:49:14.823+0000] {taskinstance.py:3498} INFO - 0 downstream tasks scheduled from follow-on schedule check
[2024-05-25T08:49:14.827+0000] {local_task_job_runner.py:222} INFO - ::endgroup::
