[2024-05-31T15:53:20.008+0000] {local_task_job_runner.py:120} INFO - ::group::Pre task execution logs
[2024-05-31T15:53:20.029+0000] {taskinstance.py:2076} INFO - Dependencies all met for dep_context=non-requeueable deps ti=<TaskInstance: my_weather_workflow_DAG_v04.group_tasks.extract_weather_data_from_api manual__2024-05-31T11:14:41.858816+00:00 [queued]>
[2024-05-31T15:53:20.038+0000] {taskinstance.py:2076} INFO - Dependencies all met for dep_context=requeueable deps ti=<TaskInstance: my_weather_workflow_DAG_v04.group_tasks.extract_weather_data_from_api manual__2024-05-31T11:14:41.858816+00:00 [queued]>
[2024-05-31T15:53:20.039+0000] {taskinstance.py:2306} INFO - Starting attempt 1 of 6
[2024-05-31T15:53:20.052+0000] {taskinstance.py:2330} INFO - Executing <Task(PythonOperator): group_tasks.extract_weather_data_from_api> on 2024-05-31 11:14:41.858816+00:00
[2024-05-31T15:53:20.060+0000] {standard_task_runner.py:90} INFO - Running: ['***', 'tasks', 'run', 'my_weather_workflow_DAG_v04', 'group_tasks.extract_weather_data_from_api', 'manual__2024-05-31T11:14:41.858816+00:00', '--job-id', '362', '--raw', '--subdir', 'DAGS_FOLDER/weather_dag.py', '--cfg-path', '/tmp/tmpbjkl8aay']
[2024-05-31T15:53:20.063+0000] {standard_task_runner.py:91} INFO - Job 362: Subtask group_tasks.extract_weather_data_from_api
[2024-05-31T15:53:20.063+0000] {logging_mixin.py:188} WARNING - /home/***/.local/lib/python3.12/site-packages/***/task/task_runner/standard_task_runner.py:61 DeprecationWarning: This process (pid=483) is multi-threaded, use of fork() may lead to deadlocks in the child.
[2024-05-31T15:53:20.064+0000] {standard_task_runner.py:63} INFO - Started process 485 to run task
[2024-05-31T15:53:20.123+0000] {task_command.py:426} INFO - Running <TaskInstance: my_weather_workflow_DAG_v04.group_tasks.extract_weather_data_from_api manual__2024-05-31T11:14:41.858816+00:00 [running]> on host cd9caf1c47f0
[2024-05-31T15:53:20.247+0000] {taskinstance.py:2648} INFO - Exporting env vars: AIRFLOW_CTX_DAG_OWNER='Khang' AIRFLOW_CTX_DAG_ID='my_weather_workflow_DAG_v04' AIRFLOW_CTX_TASK_ID='group_tasks.extract_weather_data_from_api' AIRFLOW_CTX_EXECUTION_DATE='2024-05-31T11:14:41.858816+00:00' AIRFLOW_CTX_TRY_NUMBER='1' AIRFLOW_CTX_DAG_RUN_ID='manual__2024-05-31T11:14:41.858816+00:00'
[2024-05-31T15:53:20.248+0000] {taskinstance.py:430} INFO - ::endgroup::
[2024-05-31T15:53:20.261+0000] {taskinstance.py:441} INFO - ::group::Post task execution logs
[2024-05-31T15:53:20.261+0000] {taskinstance.py:2905} ERROR - Task failed with exception
Traceback (most recent call last):
  File "/home/airflow/.local/lib/python3.12/site-packages/airflow/models/taskinstance.py", line 465, in _execute_task
    result = _execute_callable(context=context, **execute_callable_kwargs)
             ^^^^^^^^^^^^^^^^^^^^^^^^^^^^^^^^^^^^^^^^^^^^^^^^^^^^^^^^^^^^^
  File "/home/airflow/.local/lib/python3.12/site-packages/airflow/models/taskinstance.py", line 432, in _execute_callable
    return execute_callable(context=context, **execute_callable_kwargs)
           ^^^^^^^^^^^^^^^^^^^^^^^^^^^^^^^^^^^^^^^^^^^^^^^^^^^^^^^^^^^^
  File "/home/airflow/.local/lib/python3.12/site-packages/airflow/models/baseoperator.py", line 400, in wrapper
    return func(self, *args, **kwargs)
           ^^^^^^^^^^^^^^^^^^^^^^^^^^^
  File "/home/airflow/.local/lib/python3.12/site-packages/airflow/operators/python.py", line 235, in execute
    return_value = self.execute_callable()
                   ^^^^^^^^^^^^^^^^^^^^^^^
  File "/home/airflow/.local/lib/python3.12/site-packages/airflow/operators/python.py", line 252, in execute_callable
    return self.python_callable(*self.op_args, **self.op_kwargs)
           ^^^^^^^^^^^^^^^^^^^^^^^^^^^^^^^^^^^^^^^^^^^^^^^^^^^^^
  File "/opt/airflow/dags/weather_dag.py", line 158, in extract_weather_data_from_api
    endpoint = f'/data/2.5/weather?lat={kwargs['latitude']}&lon={kwargs['longtitude']}&appid={kwargs['API_KEY']}',
                                                                 ~~~~~~^^^^^^^^^^^^^^
KeyError: 'longtitude'
[2024-05-31T15:53:20.279+0000] {taskinstance.py:1206} INFO - Marking task as UP_FOR_RETRY. dag_id=my_weather_workflow_DAG_v04, task_id=group_tasks.extract_weather_data_from_api, run_id=manual__2024-05-31T11:14:41.858816+00:00, execution_date=20240531T111441, start_date=20240531T155320, end_date=20240531T155320
[2024-05-31T15:53:20.291+0000] {standard_task_runner.py:110} ERROR - Failed to execute job 362 for task group_tasks.extract_weather_data_from_api ('longtitude'; 485)
[2024-05-31T15:53:20.319+0000] {local_task_job_runner.py:240} INFO - Task exited with return code 1
[2024-05-31T15:53:20.342+0000] {taskinstance.py:3498} INFO - 0 downstream tasks scheduled from follow-on schedule check
[2024-05-31T15:53:20.345+0000] {local_task_job_runner.py:222} INFO - ::endgroup::
