[2024-05-30T05:51:44.523+0000] {local_task_job_runner.py:120} INFO - ::group::Pre task execution logs
[2024-05-30T05:51:44.542+0000] {taskinstance.py:2076} INFO - Dependencies all met for dep_context=non-requeueable deps ti=<TaskInstance: my_weather_workflow_DAG_v04.load_csv_to_postgres manual__2024-05-30T03:47:59.479456+00:00 [queued]>
[2024-05-30T05:51:44.552+0000] {taskinstance.py:2076} INFO - Dependencies all met for dep_context=requeueable deps ti=<TaskInstance: my_weather_workflow_DAG_v04.load_csv_to_postgres manual__2024-05-30T03:47:59.479456+00:00 [queued]>
[2024-05-30T05:51:44.553+0000] {taskinstance.py:2306} INFO - Starting attempt 1 of 6
[2024-05-30T05:51:44.566+0000] {taskinstance.py:2330} INFO - Executing <Task(PythonOperator): load_csv_to_postgres> on 2024-05-30 03:47:59.479456+00:00
[2024-05-30T05:51:44.574+0000] {logging_mixin.py:188} WARNING - /home/***/.local/lib/python3.12/site-packages/***/task/task_runner/standard_task_runner.py:61 DeprecationWarning: This process (pid=4537) is multi-threaded, use of fork() may lead to deadlocks in the child.
[2024-05-30T05:51:44.576+0000] {standard_task_runner.py:63} INFO - Started process 4539 to run task
[2024-05-30T05:51:44.574+0000] {standard_task_runner.py:90} INFO - Running: ['***', 'tasks', 'run', 'my_weather_workflow_DAG_v04', 'load_csv_to_postgres', 'manual__2024-05-30T03:47:59.479456+00:00', '--job-id', '102', '--raw', '--subdir', 'DAGS_FOLDER/weather_dag.py', '--cfg-path', '/tmp/tmptj4trgfi']
[2024-05-30T05:51:44.577+0000] {standard_task_runner.py:91} INFO - Job 102: Subtask load_csv_to_postgres
[2024-05-30T05:51:44.635+0000] {task_command.py:426} INFO - Running <TaskInstance: my_weather_workflow_DAG_v04.load_csv_to_postgres manual__2024-05-30T03:47:59.479456+00:00 [running]> on host cd9caf1c47f0
[2024-05-30T05:51:44.734+0000] {taskinstance.py:2648} INFO - Exporting env vars: AIRFLOW_CTX_DAG_OWNER='Khang' AIRFLOW_CTX_DAG_ID='my_weather_workflow_DAG_v04' AIRFLOW_CTX_TASK_ID='load_csv_to_postgres' AIRFLOW_CTX_EXECUTION_DATE='2024-05-30T03:47:59.479456+00:00' AIRFLOW_CTX_TRY_NUMBER='1' AIRFLOW_CTX_DAG_RUN_ID='manual__2024-05-30T03:47:59.479456+00:00'
[2024-05-30T05:51:44.735+0000] {taskinstance.py:430} INFO - ::endgroup::
[2024-05-30T05:51:44.764+0000] {taskinstance.py:441} INFO - ::group::Post task execution logs
[2024-05-30T05:51:44.765+0000] {taskinstance.py:2905} ERROR - Task failed with exception
Traceback (most recent call last):
  File "/home/airflow/.local/lib/python3.12/site-packages/airflow/models/taskinstance.py", line 465, in _execute_task
    result = _execute_callable(context=context, **execute_callable_kwargs)
             ^^^^^^^^^^^^^^^^^^^^^^^^^^^^^^^^^^^^^^^^^^^^^^^^^^^^^^^^^^^^^
  File "/home/airflow/.local/lib/python3.12/site-packages/airflow/models/taskinstance.py", line 432, in _execute_callable
    return execute_callable(context=context, **execute_callable_kwargs)
           ^^^^^^^^^^^^^^^^^^^^^^^^^^^^^^^^^^^^^^^^^^^^^^^^^^^^^^^^^^^^
  File "/home/airflow/.local/lib/python3.12/site-packages/airflow/models/baseoperator.py", line 400, in wrapper
    return func(self, *args, **kwargs)
           ^^^^^^^^^^^^^^^^^^^^^^^^^^^
  File "/home/airflow/.local/lib/python3.12/site-packages/airflow/operators/python.py", line 235, in execute
    return_value = self.execute_callable()
                   ^^^^^^^^^^^^^^^^^^^^^^^
  File "/home/airflow/.local/lib/python3.12/site-packages/airflow/operators/python.py", line 252, in execute_callable
    return self.python_callable(*self.op_args, **self.op_kwargs)
           ^^^^^^^^^^^^^^^^^^^^^^^^^^^^^^^^^^^^^^^^^^^^^^^^^^^^^
  File "/opt/airflow/dags/weather_dag.py", line 123, in load_csv_to_postgres
    hook.copy_expert(
TypeError: PostgresHook.copy_expert() got an unexpected keyword argument 'file_name'
[2024-05-30T05:51:44.782+0000] {taskinstance.py:1206} INFO - Marking task as UP_FOR_RETRY. dag_id=my_weather_workflow_DAG_v04, task_id=load_csv_to_postgres, run_id=manual__2024-05-30T03:47:59.479456+00:00, execution_date=20240530T034759, start_date=20240530T055144, end_date=20240530T055144
[2024-05-30T05:51:44.793+0000] {standard_task_runner.py:110} ERROR - Failed to execute job 102 for task load_csv_to_postgres (PostgresHook.copy_expert() got an unexpected keyword argument 'file_name'; 4539)
[2024-05-30T05:51:44.830+0000] {local_task_job_runner.py:240} INFO - Task exited with return code 1
[2024-05-30T05:51:44.853+0000] {taskinstance.py:3498} INFO - 0 downstream tasks scheduled from follow-on schedule check
[2024-05-30T05:51:44.856+0000] {local_task_job_runner.py:222} INFO - ::endgroup::
