[2024-05-30T05:58:16.117+0000] {local_task_job_runner.py:120} INFO - ::group::Pre task execution logs
[2024-05-30T05:58:16.149+0000] {taskinstance.py:2076} INFO - Dependencies all met for dep_context=non-requeueable deps ti=<TaskInstance: my_weather_workflow_DAG_v04.load_csv_to_postgres manual__2024-05-30T03:47:59.479456+00:00 [queued]>
[2024-05-30T05:58:16.159+0000] {taskinstance.py:2076} INFO - Dependencies all met for dep_context=requeueable deps ti=<TaskInstance: my_weather_workflow_DAG_v04.load_csv_to_postgres manual__2024-05-30T03:47:59.479456+00:00 [queued]>
[2024-05-30T05:58:16.161+0000] {taskinstance.py:2306} INFO - Starting attempt 5 of 10
[2024-05-30T05:58:16.173+0000] {taskinstance.py:2330} INFO - Executing <Task(PythonOperator): load_csv_to_postgres> on 2024-05-30 03:47:59.479456+00:00
[2024-05-30T05:58:16.181+0000] {logging_mixin.py:188} WARNING - /home/***/.local/lib/python3.12/site-packages/***/task/task_runner/standard_task_runner.py:61 DeprecationWarning: This process (pid=4785) is multi-threaded, use of fork() may lead to deadlocks in the child.
[2024-05-30T05:58:16.182+0000] {standard_task_runner.py:63} INFO - Started process 4787 to run task
[2024-05-30T05:58:16.181+0000] {standard_task_runner.py:90} INFO - Running: ['***', 'tasks', 'run', 'my_weather_workflow_DAG_v04', 'load_csv_to_postgres', 'manual__2024-05-30T03:47:59.479456+00:00', '--job-id', '126', '--raw', '--subdir', 'DAGS_FOLDER/weather_dag.py', '--cfg-path', '/tmp/tmpa3m4q5t2']
[2024-05-30T05:58:16.183+0000] {standard_task_runner.py:91} INFO - Job 126: Subtask load_csv_to_postgres
[2024-05-30T05:58:16.243+0000] {task_command.py:426} INFO - Running <TaskInstance: my_weather_workflow_DAG_v04.load_csv_to_postgres manual__2024-05-30T03:47:59.479456+00:00 [running]> on host cd9caf1c47f0
[2024-05-30T05:58:16.338+0000] {taskinstance.py:2648} INFO - Exporting env vars: AIRFLOW_CTX_DAG_OWNER='Khang' AIRFLOW_CTX_DAG_ID='my_weather_workflow_DAG_v04' AIRFLOW_CTX_TASK_ID='load_csv_to_postgres' AIRFLOW_CTX_EXECUTION_DATE='2024-05-30T03:47:59.479456+00:00' AIRFLOW_CTX_TRY_NUMBER='5' AIRFLOW_CTX_DAG_RUN_ID='manual__2024-05-30T03:47:59.479456+00:00'
[2024-05-30T05:58:16.339+0000] {taskinstance.py:430} INFO - ::endgroup::
[2024-05-30T05:58:16.375+0000] {base.py:84} INFO - Using connection ID 'postgres_connection_id' for task execution.
[2024-05-30T05:58:16.389+0000] {taskinstance.py:441} INFO - ::group::Post task execution logs
[2024-05-30T05:58:16.390+0000] {taskinstance.py:2905} ERROR - Task failed with exception
Traceback (most recent call last):
  File "/home/airflow/.local/lib/python3.12/site-packages/airflow/models/taskinstance.py", line 465, in _execute_task
    result = _execute_callable(context=context, **execute_callable_kwargs)
             ^^^^^^^^^^^^^^^^^^^^^^^^^^^^^^^^^^^^^^^^^^^^^^^^^^^^^^^^^^^^^
  File "/home/airflow/.local/lib/python3.12/site-packages/airflow/models/taskinstance.py", line 432, in _execute_callable
    return execute_callable(context=context, **execute_callable_kwargs)
           ^^^^^^^^^^^^^^^^^^^^^^^^^^^^^^^^^^^^^^^^^^^^^^^^^^^^^^^^^^^^
  File "/home/airflow/.local/lib/python3.12/site-packages/airflow/models/baseoperator.py", line 400, in wrapper
    return func(self, *args, **kwargs)
           ^^^^^^^^^^^^^^^^^^^^^^^^^^^
  File "/home/airflow/.local/lib/python3.12/site-packages/airflow/operators/python.py", line 235, in execute
    return_value = self.execute_callable()
                   ^^^^^^^^^^^^^^^^^^^^^^^
  File "/home/airflow/.local/lib/python3.12/site-packages/airflow/operators/python.py", line 252, in execute_callable
    return self.python_callable(*self.op_args, **self.op_kwargs)
           ^^^^^^^^^^^^^^^^^^^^^^^^^^^^^^^^^^^^^^^^^^^^^^^^^^^^^
  File "/opt/airflow/dags/weather_dag.py", line 127, in load_csv_to_postgres
    cursor.copy_expert("COPY cities FROM stdin WITH CSV HEADER", f)
psycopg2.errors.BadCopyFileFormat: missing data for column "created_at"
CONTEXT:  COPY cities, line 2: "Q1854,Vietnam,Ho Chi Minh City,9389720,10.82302,106.62965"

[2024-05-30T05:58:16.407+0000] {taskinstance.py:1206} INFO - Marking task as UP_FOR_RETRY. dag_id=my_weather_workflow_DAG_v04, task_id=load_csv_to_postgres, run_id=manual__2024-05-30T03:47:59.479456+00:00, execution_date=20240530T034759, start_date=20240530T055816, end_date=20240530T055816
[2024-05-30T05:58:16.419+0000] {standard_task_runner.py:110} ERROR - Failed to execute job 126 for task load_csv_to_postgres (missing data for column "created_at"
CONTEXT:  COPY cities, line 2: "Q1854,Vietnam,Ho Chi Minh City,9389720,10.82302,106.62965"
; 4787)
[2024-05-30T05:58:16.436+0000] {local_task_job_runner.py:240} INFO - Task exited with return code 1
[2024-05-30T05:58:16.457+0000] {taskinstance.py:3498} INFO - 0 downstream tasks scheduled from follow-on schedule check
[2024-05-30T05:58:16.459+0000] {local_task_job_runner.py:222} INFO - ::endgroup::
