[2024-05-30T05:25:40.004+0000] {local_task_job_runner.py:120} INFO - ::group::Pre task execution logs
[2024-05-30T05:25:40.024+0000] {taskinstance.py:2076} INFO - Dependencies all met for dep_context=non-requeueable deps ti=<TaskInstance: my_weather_workflow_DAG_v04.check_data_is_exist manual__2024-05-30T03:47:59.479456+00:00 [queued]>
[2024-05-30T05:25:40.031+0000] {taskinstance.py:2076} INFO - Dependencies all met for dep_context=requeueable deps ti=<TaskInstance: my_weather_workflow_DAG_v04.check_data_is_exist manual__2024-05-30T03:47:59.479456+00:00 [queued]>
[2024-05-30T05:25:40.032+0000] {taskinstance.py:2306} INFO - Starting attempt 6 of 9
[2024-05-30T05:25:40.047+0000] {taskinstance.py:2330} INFO - Executing <Task(BranchPythonOperator): check_data_is_exist> on 2024-05-30 03:47:59.479456+00:00
[2024-05-30T05:25:40.058+0000] {logging_mixin.py:188} WARNING - /home/***/.local/lib/python3.12/site-packages/***/task/task_runner/standard_task_runner.py:61 DeprecationWarning: This process (pid=4171) is multi-threaded, use of fork() may lead to deadlocks in the child.
[2024-05-30T05:25:40.060+0000] {standard_task_runner.py:63} INFO - Started process 4173 to run task
[2024-05-30T05:25:40.058+0000] {standard_task_runner.py:90} INFO - Running: ['***', 'tasks', 'run', 'my_weather_workflow_DAG_v04', 'check_data_is_exist', 'manual__2024-05-30T03:47:59.479456+00:00', '--job-id', '94', '--raw', '--subdir', 'DAGS_FOLDER/weather_dag.py', '--cfg-path', '/tmp/tmpfli8byay']
[2024-05-30T05:25:40.061+0000] {standard_task_runner.py:91} INFO - Job 94: Subtask check_data_is_exist
[2024-05-30T05:25:40.133+0000] {task_command.py:426} INFO - Running <TaskInstance: my_weather_workflow_DAG_v04.check_data_is_exist manual__2024-05-30T03:47:59.479456+00:00 [running]> on host cd9caf1c47f0
[2024-05-30T05:25:40.239+0000] {taskinstance.py:2648} INFO - Exporting env vars: AIRFLOW_CTX_DAG_OWNER='Khang' AIRFLOW_CTX_DAG_ID='my_weather_workflow_DAG_v04' AIRFLOW_CTX_TASK_ID='check_data_is_exist' AIRFLOW_CTX_EXECUTION_DATE='2024-05-30T03:47:59.479456+00:00' AIRFLOW_CTX_TRY_NUMBER='6' AIRFLOW_CTX_DAG_RUN_ID='manual__2024-05-30T03:47:59.479456+00:00'
[2024-05-30T05:25:40.240+0000] {taskinstance.py:430} INFO - ::endgroup::
[2024-05-30T05:25:40.255+0000] {baseoperator.py:399} WARNING - BranchPythonOperator.execute cannot be called outside TaskInstance!
[2024-05-30T05:25:40.280+0000] {base.py:84} INFO - Using connection ID 'postgres_connection_id' for task execution.
[2024-05-30T05:25:40.289+0000] {sql.py:470} INFO - Running statement: SELECT COUNT(*) FROM cities WHERE wiki_id = Q1854, parameters: None
[2024-05-30T05:25:40.290+0000] {taskinstance.py:441} INFO - ::group::Post task execution logs
[2024-05-30T05:25:40.291+0000] {taskinstance.py:2905} ERROR - Task failed with exception
Traceback (most recent call last):
  File "/home/airflow/.local/lib/python3.12/site-packages/airflow/models/taskinstance.py", line 465, in _execute_task
    result = _execute_callable(context=context, **execute_callable_kwargs)
             ^^^^^^^^^^^^^^^^^^^^^^^^^^^^^^^^^^^^^^^^^^^^^^^^^^^^^^^^^^^^^
  File "/home/airflow/.local/lib/python3.12/site-packages/airflow/models/taskinstance.py", line 432, in _execute_callable
    return execute_callable(context=context, **execute_callable_kwargs)
           ^^^^^^^^^^^^^^^^^^^^^^^^^^^^^^^^^^^^^^^^^^^^^^^^^^^^^^^^^^^^
  File "/home/airflow/.local/lib/python3.12/site-packages/airflow/models/baseoperator.py", line 400, in wrapper
    return func(self, *args, **kwargs)
           ^^^^^^^^^^^^^^^^^^^^^^^^^^^
  File "/home/airflow/.local/lib/python3.12/site-packages/airflow/operators/python.py", line 269, in execute
    return self.do_branch(context, super().execute(context))
                                   ^^^^^^^^^^^^^^^^^^^^^^^^
  File "/home/airflow/.local/lib/python3.12/site-packages/airflow/models/baseoperator.py", line 400, in wrapper
    return func(self, *args, **kwargs)
           ^^^^^^^^^^^^^^^^^^^^^^^^^^^
  File "/home/airflow/.local/lib/python3.12/site-packages/airflow/operators/python.py", line 235, in execute
    return_value = self.execute_callable()
                   ^^^^^^^^^^^^^^^^^^^^^^^
  File "/home/airflow/.local/lib/python3.12/site-packages/airflow/operators/python.py", line 252, in execute_callable
    return self.python_callable(*self.op_args, **self.op_kwargs)
           ^^^^^^^^^^^^^^^^^^^^^^^^^^^^^^^^^^^^^^^^^^^^^^^^^^^^^
  File "/opt/airflow/dags/weather_dag.py", line 110, in check_data_is_exist
    records = hook.get_records(query)
              ^^^^^^^^^^^^^^^^^^^^^^^
  File "/home/airflow/.local/lib/python3.12/site-packages/airflow/providers/common/sql/hooks/sql.py", line 283, in get_records
    return self.run(sql=sql, parameters=parameters, handler=fetch_all_handler)
           ^^^^^^^^^^^^^^^^^^^^^^^^^^^^^^^^^^^^^^^^^^^^^^^^^^^^^^^^^^^^^^^^^^^
  File "/home/airflow/.local/lib/python3.12/site-packages/airflow/providers/common/sql/hooks/sql.py", line 418, in run
    self._run_command(cur, sql_statement, parameters)
  File "/home/airflow/.local/lib/python3.12/site-packages/airflow/providers/common/sql/hooks/sql.py", line 475, in _run_command
    cur.execute(sql_statement)
psycopg2.errors.UndefinedColumn: column "q1854" does not exist
LINE 1: SELECT COUNT(*) FROM cities WHERE wiki_id = Q1854
                                                    ^

[2024-05-30T05:25:40.309+0000] {taskinstance.py:1206} INFO - Marking task as UP_FOR_RETRY. dag_id=my_weather_workflow_DAG_v04, task_id=check_data_is_exist, run_id=manual__2024-05-30T03:47:59.479456+00:00, execution_date=20240530T034759, start_date=20240530T052540, end_date=20240530T052540
[2024-05-30T05:25:40.321+0000] {standard_task_runner.py:110} ERROR - Failed to execute job 94 for task check_data_is_exist (column "q1854" does not exist
LINE 1: SELECT COUNT(*) FROM cities WHERE wiki_id = Q1854
                                                    ^
; 4173)
[2024-05-30T05:25:40.355+0000] {local_task_job_runner.py:240} INFO - Task exited with return code 1
[2024-05-30T05:25:40.373+0000] {taskinstance.py:3498} INFO - 0 downstream tasks scheduled from follow-on schedule check
[2024-05-30T05:25:40.376+0000] {local_task_job_runner.py:222} INFO - ::endgroup::
