[2024-05-25T14:10:49.153+0000] {local_task_job_runner.py:120} INFO - ::group::Pre task execution logs
[2024-05-25T14:10:49.180+0000] {taskinstance.py:2076} INFO - Dependencies all met for dep_context=non-requeueable deps ti=<TaskInstance: my_weather_workflow_DAG_v03.transform_data_response manual__2024-05-25T14:09:31.733825+00:00 [queued]>
[2024-05-25T14:10:49.190+0000] {taskinstance.py:2076} INFO - Dependencies all met for dep_context=requeueable deps ti=<TaskInstance: my_weather_workflow_DAG_v03.transform_data_response manual__2024-05-25T14:09:31.733825+00:00 [queued]>
[2024-05-25T14:10:49.191+0000] {taskinstance.py:2306} INFO - Starting attempt 3 of 8
[2024-05-25T14:10:49.206+0000] {taskinstance.py:2330} INFO - Executing <Task(PythonOperator): transform_data_response> on 2024-05-25 14:09:31.733825+00:00
[2024-05-25T14:10:49.216+0000] {standard_task_runner.py:90} INFO - Running: ['***', 'tasks', 'run', 'my_weather_workflow_DAG_v03', 'transform_data_response', 'manual__2024-05-25T14:09:31.733825+00:00', '--job-id', '126', '--raw', '--subdir', 'DAGS_FOLDER/weather_dag.py', '--cfg-path', '/tmp/tmpxznw8hr5']
[2024-05-25T14:10:49.218+0000] {standard_task_runner.py:91} INFO - Job 126: Subtask transform_data_response
[2024-05-25T14:10:49.219+0000] {logging_mixin.py:188} WARNING - /home/***/.local/lib/python3.12/site-packages/***/task/task_runner/standard_task_runner.py:61 DeprecationWarning: This process (pid=431) is multi-threaded, use of fork() may lead to deadlocks in the child.
[2024-05-25T14:10:49.220+0000] {standard_task_runner.py:63} INFO - Started process 433 to run task
[2024-05-25T14:10:49.293+0000] {task_command.py:426} INFO - Running <TaskInstance: my_weather_workflow_DAG_v03.transform_data_response manual__2024-05-25T14:09:31.733825+00:00 [running]> on host c0a968b5acd8
[2024-05-25T14:10:49.617+0000] {taskinstance.py:2648} INFO - Exporting env vars: AIRFLOW_CTX_DAG_OWNER='Khang' AIRFLOW_CTX_DAG_ID='my_weather_workflow_DAG_v03' AIRFLOW_CTX_TASK_ID='transform_data_response' AIRFLOW_CTX_EXECUTION_DATE='2024-05-25T14:09:31.733825+00:00' AIRFLOW_CTX_TRY_NUMBER='4' AIRFLOW_CTX_DAG_RUN_ID='manual__2024-05-25T14:09:31.733825+00:00'
[2024-05-25T14:10:49.619+0000] {taskinstance.py:430} INFO - ::endgroup::
[2024-05-25T14:10:49.640+0000] {taskinstance.py:441} INFO - ::group::Post task execution logs
[2024-05-25T14:10:49.641+0000] {taskinstance.py:2905} ERROR - Task failed with exception
Traceback (most recent call last):
  File "/home/airflow/.local/lib/python3.12/site-packages/airflow/models/taskinstance.py", line 465, in _execute_task
    result = _execute_callable(context=context, **execute_callable_kwargs)
             ^^^^^^^^^^^^^^^^^^^^^^^^^^^^^^^^^^^^^^^^^^^^^^^^^^^^^^^^^^^^^
  File "/home/airflow/.local/lib/python3.12/site-packages/airflow/models/taskinstance.py", line 432, in _execute_callable
    return execute_callable(context=context, **execute_callable_kwargs)
           ^^^^^^^^^^^^^^^^^^^^^^^^^^^^^^^^^^^^^^^^^^^^^^^^^^^^^^^^^^^^
  File "/home/airflow/.local/lib/python3.12/site-packages/airflow/models/baseoperator.py", line 400, in wrapper
    return func(self, *args, **kwargs)
           ^^^^^^^^^^^^^^^^^^^^^^^^^^^
  File "/home/airflow/.local/lib/python3.12/site-packages/airflow/operators/python.py", line 235, in execute
    return_value = self.execute_callable()
                   ^^^^^^^^^^^^^^^^^^^^^^^
  File "/home/airflow/.local/lib/python3.12/site-packages/airflow/operators/python.py", line 252, in execute_callable
    return self.python_callable(*self.op_args, **self.op_kwargs)
           ^^^^^^^^^^^^^^^^^^^^^^^^^^^^^^^^^^^^^^^^^^^^^^^^^^^^^
  File "/opt/airflow/dags/weather_dag.py", line 82, in to_csv
    df_data.to_csv(f'/{parent_path}/data-transformed/{file_name}.csv', index=False)
  File "/home/airflow/.local/lib/python3.12/site-packages/pandas/core/generic.py", line 3902, in to_csv
    return DataFrameRenderer(formatter).to_csv(
           ^^^^^^^^^^^^^^^^^^^^^^^^^^^^^^^^^^^^
  File "/home/airflow/.local/lib/python3.12/site-packages/pandas/io/formats/format.py", line 1152, in to_csv
    csv_formatter.save()
  File "/home/airflow/.local/lib/python3.12/site-packages/pandas/io/formats/csvs.py", line 247, in save
    with get_handle(
         ^^^^^^^^^^^
  File "/home/airflow/.local/lib/python3.12/site-packages/pandas/io/common.py", line 739, in get_handle
    check_parent_directory(str(handle))
  File "/home/airflow/.local/lib/python3.12/site-packages/pandas/io/common.py", line 604, in check_parent_directory
    raise OSError(rf"Cannot save file into a non-existent directory: '{parent}'")
OSError: Cannot save file into a non-existent directory: '//opt/data-transformed'
[2024-05-25T14:10:49.665+0000] {taskinstance.py:1206} INFO - Marking task as UP_FOR_RETRY. dag_id=my_weather_workflow_DAG_v03, task_id=transform_data_response, run_id=manual__2024-05-25T14:09:31.733825+00:00, execution_date=20240525T140931, start_date=20240525T141049, end_date=20240525T141049
[2024-05-25T14:10:49.679+0000] {standard_task_runner.py:110} ERROR - Failed to execute job 126 for task transform_data_response (Cannot save file into a non-existent directory: '//opt/data-transformed'; 433)
[2024-05-25T14:10:49.717+0000] {local_task_job_runner.py:240} INFO - Task exited with return code 1
[2024-05-25T14:10:49.744+0000] {taskinstance.py:3498} INFO - 0 downstream tasks scheduled from follow-on schedule check
[2024-05-25T14:10:49.748+0000] {local_task_job_runner.py:222} INFO - ::endgroup::
