[2024-05-25T05:46:03.370+0000] {local_task_job_runner.py:120} INFO - ::group::Pre task execution logs
[2024-05-25T05:46:03.390+0000] {taskinstance.py:2076} INFO - Dependencies all met for dep_context=non-requeueable deps ti=<TaskInstance: my_weather_workflow_DAG_v03.transform_data_response manual__2024-05-25T05:20:54.595502+00:00 [queued]>
[2024-05-25T05:46:03.402+0000] {taskinstance.py:2076} INFO - Dependencies all met for dep_context=requeueable deps ti=<TaskInstance: my_weather_workflow_DAG_v03.transform_data_response manual__2024-05-25T05:20:54.595502+00:00 [queued]>
[2024-05-25T05:46:03.403+0000] {taskinstance.py:2306} INFO - Starting attempt 6 of 6
[2024-05-25T05:46:03.420+0000] {taskinstance.py:2330} INFO - Executing <Task(PythonOperator): transform_data_response> on 2024-05-25 05:20:54.595502+00:00
[2024-05-25T05:46:03.429+0000] {standard_task_runner.py:90} INFO - Running: ['***', 'tasks', 'run', 'my_weather_workflow_DAG_v03', 'transform_data_response', 'manual__2024-05-25T05:20:54.595502+00:00', '--job-id', '91', '--raw', '--subdir', 'DAGS_FOLDER/weather_dag.py', '--cfg-path', '/tmp/tmp0blzqxvo']
[2024-05-25T05:46:03.432+0000] {standard_task_runner.py:91} INFO - Job 91: Subtask transform_data_response
[2024-05-25T05:46:03.432+0000] {logging_mixin.py:188} WARNING - /home/***/.local/lib/python3.12/site-packages/***/task/task_runner/standard_task_runner.py:61 DeprecationWarning: This process (pid=1076) is multi-threaded, use of fork() may lead to deadlocks in the child.
[2024-05-25T05:46:03.433+0000] {standard_task_runner.py:63} INFO - Started process 1078 to run task
[2024-05-25T05:46:03.485+0000] {task_command.py:426} INFO - Running <TaskInstance: my_weather_workflow_DAG_v03.transform_data_response manual__2024-05-25T05:20:54.595502+00:00 [running]> on host 6ab40057742d
[2024-05-25T05:46:03.699+0000] {taskinstance.py:2648} INFO - Exporting env vars: AIRFLOW_CTX_DAG_OWNER='Khang' AIRFLOW_CTX_DAG_ID='my_weather_workflow_DAG_v03' AIRFLOW_CTX_TASK_ID='transform_data_response' AIRFLOW_CTX_EXECUTION_DATE='2024-05-25T05:20:54.595502+00:00' AIRFLOW_CTX_TRY_NUMBER='6' AIRFLOW_CTX_DAG_RUN_ID='manual__2024-05-25T05:20:54.595502+00:00'
[2024-05-25T05:46:03.700+0000] {taskinstance.py:430} INFO - ::endgroup::
[2024-05-25T05:46:03.711+0000] {taskinstance.py:441} INFO - ::group::Post task execution logs
[2024-05-25T05:46:03.712+0000] {taskinstance.py:2905} ERROR - Task failed with exception
Traceback (most recent call last):
  File "/home/airflow/.local/lib/python3.12/site-packages/airflow/models/taskinstance.py", line 465, in _execute_task
    result = _execute_callable(context=context, **execute_callable_kwargs)
             ^^^^^^^^^^^^^^^^^^^^^^^^^^^^^^^^^^^^^^^^^^^^^^^^^^^^^^^^^^^^^
  File "/home/airflow/.local/lib/python3.12/site-packages/airflow/models/taskinstance.py", line 432, in _execute_callable
    return execute_callable(context=context, **execute_callable_kwargs)
           ^^^^^^^^^^^^^^^^^^^^^^^^^^^^^^^^^^^^^^^^^^^^^^^^^^^^^^^^^^^^
  File "/home/airflow/.local/lib/python3.12/site-packages/airflow/models/baseoperator.py", line 400, in wrapper
    return func(self, *args, **kwargs)
           ^^^^^^^^^^^^^^^^^^^^^^^^^^^
  File "/home/airflow/.local/lib/python3.12/site-packages/airflow/operators/python.py", line 235, in execute
    return_value = self.execute_callable()
                   ^^^^^^^^^^^^^^^^^^^^^^^
  File "/home/airflow/.local/lib/python3.12/site-packages/airflow/operators/python.py", line 252, in execute_callable
    return self.python_callable(*self.op_args, **self.op_kwargs)
           ^^^^^^^^^^^^^^^^^^^^^^^^^^^^^^^^^^^^^^^^^^^^^^^^^^^^^
  File "/opt/airflow/dags/weather_dag.py", line 61, in to_csv
    os.mkdir(directory)
PermissionError: [Errno 13] Permission denied: '/opt/test'
[2024-05-25T05:46:03.728+0000] {taskinstance.py:1206} INFO - Marking task as FAILED. dag_id=my_weather_workflow_DAG_v03, task_id=transform_data_response, run_id=manual__2024-05-25T05:20:54.595502+00:00, execution_date=20240525T052054, start_date=20240525T054603, end_date=20240525T054603
[2024-05-25T05:46:03.740+0000] {standard_task_runner.py:110} ERROR - Failed to execute job 91 for task transform_data_response ([Errno 13] Permission denied: '/opt/test'; 1078)
[2024-05-25T05:46:03.768+0000] {local_task_job_runner.py:240} INFO - Task exited with return code 1
[2024-05-25T05:46:03.786+0000] {taskinstance.py:3498} INFO - 0 downstream tasks scheduled from follow-on schedule check
[2024-05-25T05:46:03.789+0000] {local_task_job_runner.py:222} INFO - ::endgroup::
