[2024-05-31T16:25:06.367+0000] {local_task_job_runner.py:120} INFO - ::group::Pre task execution logs
[2024-05-31T16:25:06.389+0000] {taskinstance.py:2076} INFO - Dependencies all met for dep_context=non-requeueable deps ti=<TaskInstance: my_weather_workflow_DAG_v04.group_tasks.transform_data_weather manual__2024-05-31T11:14:41.858816+00:00 [queued]>
[2024-05-31T16:25:06.397+0000] {taskinstance.py:2076} INFO - Dependencies all met for dep_context=requeueable deps ti=<TaskInstance: my_weather_workflow_DAG_v04.group_tasks.transform_data_weather manual__2024-05-31T11:14:41.858816+00:00 [queued]>
[2024-05-31T16:25:06.398+0000] {taskinstance.py:2306} INFO - Starting attempt 3 of 8
[2024-05-31T16:25:06.412+0000] {taskinstance.py:2330} INFO - Executing <Task(PythonOperator): group_tasks.transform_data_weather> on 2024-05-31 11:14:41.858816+00:00
[2024-05-31T16:25:06.419+0000] {logging_mixin.py:188} WARNING - /home/***/.local/lib/python3.12/site-packages/***/task/task_runner/standard_task_runner.py:61 DeprecationWarning: This process (pid=1439) is multi-threaded, use of fork() may lead to deadlocks in the child.
[2024-05-31T16:25:06.420+0000] {standard_task_runner.py:63} INFO - Started process 1441 to run task
[2024-05-31T16:25:06.419+0000] {standard_task_runner.py:90} INFO - Running: ['***', 'tasks', 'run', 'my_weather_workflow_DAG_v04', 'group_tasks.transform_data_weather', 'manual__2024-05-31T11:14:41.858816+00:00', '--job-id', '409', '--raw', '--subdir', 'DAGS_FOLDER/weather_dag.py', '--cfg-path', '/tmp/tmp5dse0_fr']
[2024-05-31T16:25:06.422+0000] {standard_task_runner.py:91} INFO - Job 409: Subtask group_tasks.transform_data_weather
[2024-05-31T16:25:06.482+0000] {task_command.py:426} INFO - Running <TaskInstance: my_weather_workflow_DAG_v04.group_tasks.transform_data_weather manual__2024-05-31T11:14:41.858816+00:00 [running]> on host cd9caf1c47f0
[2024-05-31T16:25:06.588+0000] {taskinstance.py:2648} INFO - Exporting env vars: AIRFLOW_CTX_DAG_OWNER='Khang' AIRFLOW_CTX_DAG_ID='my_weather_workflow_DAG_v04' AIRFLOW_CTX_TASK_ID='group_tasks.transform_data_weather' AIRFLOW_CTX_EXECUTION_DATE='2024-05-31T11:14:41.858816+00:00' AIRFLOW_CTX_TRY_NUMBER='3' AIRFLOW_CTX_DAG_RUN_ID='manual__2024-05-31T11:14:41.858816+00:00'
[2024-05-31T16:25:06.590+0000] {taskinstance.py:430} INFO - ::endgroup::
[2024-05-31T16:25:06.616+0000] {taskinstance.py:441} INFO - ::group::Post task execution logs
[2024-05-31T16:25:06.617+0000] {taskinstance.py:2905} ERROR - Task failed with exception
Traceback (most recent call last):
  File "/home/airflow/.local/lib/python3.12/site-packages/airflow/models/taskinstance.py", line 465, in _execute_task
    result = _execute_callable(context=context, **execute_callable_kwargs)
             ^^^^^^^^^^^^^^^^^^^^^^^^^^^^^^^^^^^^^^^^^^^^^^^^^^^^^^^^^^^^^
  File "/home/airflow/.local/lib/python3.12/site-packages/airflow/models/taskinstance.py", line 432, in _execute_callable
    return execute_callable(context=context, **execute_callable_kwargs)
           ^^^^^^^^^^^^^^^^^^^^^^^^^^^^^^^^^^^^^^^^^^^^^^^^^^^^^^^^^^^^
  File "/home/airflow/.local/lib/python3.12/site-packages/airflow/models/baseoperator.py", line 400, in wrapper
    return func(self, *args, **kwargs)
           ^^^^^^^^^^^^^^^^^^^^^^^^^^^
  File "/home/airflow/.local/lib/python3.12/site-packages/airflow/operators/python.py", line 235, in execute
    return_value = self.execute_callable()
                   ^^^^^^^^^^^^^^^^^^^^^^^
  File "/home/airflow/.local/lib/python3.12/site-packages/airflow/operators/python.py", line 252, in execute_callable
    return self.python_callable(*self.op_args, **self.op_kwargs)
           ^^^^^^^^^^^^^^^^^^^^^^^^^^^^^^^^^^^^^^^^^^^^^^^^^^^^^
  File "/opt/airflow/dags/weather_dag.py", line 134, in transform_data_weather
    weather_description = data['weather'][0]['description']
                          ~~~~^^^^^^^^^^^
KeyError: 'weather'
[2024-05-31T16:25:06.636+0000] {taskinstance.py:1206} INFO - Marking task as UP_FOR_RETRY. dag_id=my_weather_workflow_DAG_v04, task_id=group_tasks.transform_data_weather, run_id=manual__2024-05-31T11:14:41.858816+00:00, execution_date=20240531T111441, start_date=20240531T162506, end_date=20240531T162506
[2024-05-31T16:25:06.649+0000] {standard_task_runner.py:110} ERROR - Failed to execute job 409 for task group_tasks.transform_data_weather ('weather'; 1441)
[2024-05-31T16:25:06.676+0000] {local_task_job_runner.py:240} INFO - Task exited with return code 1
[2024-05-31T16:25:06.698+0000] {taskinstance.py:3498} INFO - 0 downstream tasks scheduled from follow-on schedule check
[2024-05-31T16:25:06.701+0000] {local_task_job_runner.py:222} INFO - ::endgroup::
